Workbook

Sheet  Ingredients Library
A1: TS GRANULE LIBRARY FOR AUSTRALIA | D1: CURRENT AT DATE: | E1: 46083 | F1: REVISION No: | G1: 15 | J1: HEADING COLOUR INDICATES COLUMNS HIGHLIGHTED FOR IMPORT and use by Customers
A2: Required for formulation | Q2: Printed on label | R2: Calculation fields for label quantities and price | AB2: Calculation field for total pod weight to print on label | AC2: Fields to guide and limit granule inputs to formulation Data will be updated. Limits compared to COLUMN R Justification in Col DS | AL2: Summary of allergen fields to be printed on label. Final expression TBC | BY2: WARNINGS To be printed on label | BZ2: Excipients to be summarised and printed on label | DT2: Prescription Builder Software Description
A3: TSI Ingredients Library Summary Code | B3: Available (A) / Unavailable (U) Ingredient | C3: Granule Price $AUD/granule | D3: Active Ingredient | E3: Common Name - TSI Global granule name (preferred name) | F3: TSIC Active Code | G3: Scientific Name | H3: Latin Binomial | I3: TGA Approved Name | J3: Plant Part | K3: Preparation Type | L3: Extract Ratio | M3: Extraction Solvents | N3: Standardisation | O3: Potency | P3: TGA Ingredient Expression (For reference only) | Q3: Label Expression (To be printed on box back label) | R3: TGA Label Expression Quantity Line 1 | S3: Unit of Measure Line 1 | T3: TGA Label Expression Quantity Line 2 | U3: Unit of Measure Line 2 | V3: TGA Label Expression Quantity Line 3 | W3: Unit of Measure Line 3 | X3: TGA Label Expression Quantity Line 4 | Y3: Unit of Measure Line 4 | Z3: Questions | AA3: Answers | AB3: Granule Weight (mg) | AC3: Maximum Dose (COPY UNITS FROM Column S) | AD3: Recommended Dose (COPY UNITS FROM Column S) | AE3: Active Ingredient Category | AF3: Regulatory Status1 | AG3: HS Code | AH3: Department of Agriculture, Fisheries and Forestry (DAFF) BICON Case | AI3: Department of Agriculture, Fisheries and Forestry (DAFF) Import Permit | AJ3: Convention on International Trade in Endangered Species (CITES) | AK3: Other Import Requirements | AL3: Declarable Ingredients and Allergens (aspartame) | AM3: Declarable Ingredients and Allergens (benzoates) | AN3: Declarable Ingredients and Allergens (celery) | AO3: Declarable Ingredients and Allergens (crustacean) | AP3: Declarable Ingredients and Allergens (dairy) | AQ3: Declarable Ingredients and Allergens (egg) | AR3: Declarable Ingredients and Allergens (fish) | AS3: Declarable Ingredients and Allergens (gluten) | AT3: Declarable Ingredients and Allergens (hydroxybenzoic acid esters) | AU3: Declarable Ingredients and Allergens (peanut) | AV3: Declarable Ingredients and Allergens (phenylalanine) | AW3: Declarable Ingredients and Allergens (pollen) | AX3: Declarable Ingredients and Allergens (propolis) | AY3: Declarable Ingredients and Allergens (royal jelly) | AZ3: Declarable Ingredients and Allergens (sesame) | BA3: Declarable Ingredients and Allergens (soy) | BB3: Declarable Ingredients and Allergens (sulfites) | BC3: Declarable Ingredients and Allergens (tree nuts) | BD3: Declarable Ingredients and Allergens (potassium) | BE3: Declarable Ingredients and Allergens (potassium quantity) | BF3: Declarable Ingredients and Allergens (potassium unit of measure) | BG3: Declarable Ingredients and Allergens (saccharin) | BH3: Declarable Ingredients and Allergens (sodium) | BI3: Declarable Ingredients and Allergens (sodium quantity) | BJ3: Declarable Ingredients and Allergens (sodium unit of measure) | BK3: Declarable Ingredients and Allergens (sorbates) | BL3: Declarable Ingredients and Allergens (sucralose) | BM3: Declarable Ingredients and Allergens (sugars - all) | BN3: Declarable Ingredients and Allergens (sugars - all quantity) | BO3: Declarable Ingredients and Allergens (sugars - all unit of measure) | BP3: Declarable Ingredients and Allergens (sugars - galactose) | BQ3: Declarable Ingredients and Allergens (sugars - lactose) | BR3: Declarable Ingredients and Allergens (sugar alcohols) | BS3: Declarable Ingredients and Allergens (sugar alcohols quantity) | BT3: Declarable Ingredients and Allergens (sugar alcohols unit of measure) | BU3: Declarable Ingredients and Allergens (tartrazine) | BV3: TGA Ingredient ID | BW3: TGA Restrictions (As stated in TGA Permitted Ingredients Determination and associated regulations) | BX3: TGA Warnings (As stated in TGA Permitted Ingredients Determination and associated regulations) | BY3: Compound Pharmacy Required Label Warnings (To be printed on box back label) | BZ3: Excipient (acacia) | CA3: Excipient (butylated hydroxytoluene) | CB3: Excipient (calcium hydrogen phosphate) | CC3: Excipient (carmellose sodium) | CD3: Excipient (casein) | CE3: Excipient (colloidal anhydrous silica) | CF3: Excipient (croscarmellose sodium) | CG3: Excipient (d-alpha-tocopherol) | CH3: Excipient (dl-alpha-tocopherol) | CI3: Excipient (dioleoylpho (sphatidylcholine) | CJ3: Excipient (ethanol) | CK3: Excipient (ethylcellulose) | CL3: Excipient (vanilla flavour) | CM3: Excipient (gelatin) | CN3: Excipient (glacial acetic acid) | CO3: Excipient (glucose) | CP3: Excipient (glucose monohydrate) | CQ3: Excipient (glycerol) | CR3: Excipient (hydrogenated vegetable oil) | CS3: Excipient (hyprolose) | CT3: Excipient (hypromellose) | CU3: Excipient (isomalt) | CV3: Excipient (isomaltooligosaccharides) | CW3: Excipient (lecithin) | CX3: Excipient (magnesium stearate) | CY3: Excipient (maize starch) | CZ3: Excipient (maltodextrin) | DA3: Excipient (medium chain triglycerides) | DB3: Excipient (microcrystalline cellulose) | DC3: Excipient (mixed carotenoids) | DD3: Excipient (pea starch) | DE3: Excipient (phytosterol complex) | DF3: Excipient (poliglusam) | DG3: Excipient (pregelatinised starch) | DH3: Excipient (silicon dioxide) | DI3: Excipient (sodium alginate) | DJ3: Excipient (sodium caseinate) | DK3: Excipient (sodium starch glycollate) | DL3: Excipient (sodium stearyl lactate) | DM3: Excipient (squalene) | DN3: Excipient (sucrose) | DO3: Excipient (tapioca starch) | DP3: Excipient (tocopherol) | DQ3: Non-GMO | DR3: Halal Suitable (NOT Certified) | DS3: Comments - including Nof1 Max Dose Justification from 17/2/2026 | DT3: Prescribing Software Description: To appear as separate lines in the Practitioner formulation website page | DU3: TGA Required Label Warnings NOT to be printed - see Column BY for printed label warning requirements for Pharmacy
A4: 31P0017 | B4: A | C4: 0.12 | E4: Aluminium Cup | AH4: n/a | AI4: n/a | AJ4: n/a | AK4: No
A5: 31M0133 | B5: A | C5: 0.02 | E5: Black Foil Lid Custom | AH5: n/a | AI5: n/a | AJ5: n/a | AK5: No
A6: W010001000 | B6: A | C6: 0.0096 | D6: Ginseng (Panax quinquefolius) extract (root) (standardized to 9% ginsenosides) | E6: American ginseng | F6: A2716 | G6: Panax quinquefolius | H6: Panax quinquefolius | I6: Panax quinquefolius | J6: root | K6: extract dry concentrate standardised | L6: 4:1 | M6: 60% ethanol:water | N6: 9% ginsenosides | O6: - | P6: Panax quinquefolius root ext. dry conc. std. 4:1 (60:40 E:W) Equiv. Panax quinquefolius dry root Equiv. Ginsenosides 9% contains maltodextrin 20% | Q6: Panax quinquefolius (American ginseng) root extract equivalent Panax quinquefolius dry root equivalent ginsenosides | R6: 10 | S6: mg | T6: 40 | U6: mg | V6: 0.9 | W6: mg | Z6: - | AB6: 18.8102 | AC6: 1000 | AD6: 400 | AE6: Herb | AF6: Export Only, Listed, OTC, Prescription | AG6: 1302.19.90 | AH6: Highly refined organic chemicals and substances | AI6: Not required | AJ6: Not included in any CITES Appendix | AK6: No | AP6: dairy | BA6: soy | BB6: sulfites | BH6: sodium | BI6: 0.1 | BJ6: mg | BM6: sugars | BN6: 0.031 | BO6: mg | BV6: 108215 | BW6: No restrictions. | BX6: No warnings. | BY6: No warnings. | CC6: carmellose sodium | CE6: colloidal anhydrous silica | CL6: vanilla flavour | CP6: glucose monohydrate | CQ6: glycerol | CT6: hypromellose | CW6: lecithin | CX6: magnesium stearate | CZ6: maltodextrin | DB6: microcrystalline cellulose | DQ6: Yes | DR6: Yes | DS6: TR 1-3 g/day dried herb equivalent https://pubmed.ncbi.nlm.nih.gov/10761967/ happy with this TR 400 - 750 mg of a 4:1 extract | DT6: Panax quinquefolius (American ginseng) root extract (4:1) equivalent Panax quinquefolius dry root equivalent ginsenosides (9%) | DU6: No warnings.
A7: W010003000 | B7: A | C7: 0.0122 | D7: Ashwagandha (Withania somnifera) extract (root) (standardised to 2.5% withanolides) | E7: Ashwagandha | F7: A730 | G7: Withania somnifera | H7: Withania somnifera | I7: Withania somnifera | J7: root | K7: extract dry concentrate standardised | L7: 10-15:1 | M7: 80% ethanol:water | N7: 2.5% withanolides | O7: - | P7: Withania somnifera (Ashwagandha) root ex dry conc std (10:1, 80% E/W) Equiv. Withania somnifera root dry Equiv. Withanolides (2.5%) | Q7: Withania somnifera (Ashwagandha) root extract equivalent Withania somnifera dry root equivalent withanolides | R7: 10 | S7: mg | T7: 100 | U7: mg | V7: 0.25 | W7: mg | Z7: Please confirm the name and quantity of any excipients present? | AA7: NMT 5% maltodextrin | AB7: 19.4702 | AC7: 800 | AD7: 300 | AE7: Herb | AF7: Export Only, Listed, OTC, Prescription | AG7: 1302.19.90 | AH7: Highly refined organic chemicals and substances | AI7: Not required | AJ7: Not included in any CITES Appendix | AK7: No | AP7: dairy | BA7: soy | BB7: sulfites | BH7: sodium | BI7: 0.11 | BJ7: mg | BM7: sugars | BN7: 0.035 | BO7: mg | BV7: 84964 | BW7: No restrictions. | BX7: The medicine requires the following warning statement on the label:- (WITHANIA) 'If you are pregnant, or considering becoming pregnant, do not take without consulting a health professional' (or words to that effect) unless: (a) the plant part is root; (b) the plant preparation is an extract; (c) the extraction solvents are only water, ethanol or methanol; and (d) the maximum recommended daily dose of the medicine contains no more than the equivalent quantity of 12 g dry root | BY7: No warnings. | CC7: carmellose sodium | CE7: colloidal anhydrous silica | CJ7: ethanol | CL7: vanilla flavour | CN7: glacial acetic acid | CP7: glucose monohydrate | CW7: lecithin | CX7: magnesium stearate | CZ7: maltodextrin | DB7: microcrystalline cellulose | DF7: poliglusam | DQ7: Yes | DR7: Yes | DS7: Therapeutic range 3-6 gm daily MT TR 300mg - 600 mg of a 10:1 extract UL https://www.researchgate.net/publication/232814045_Exploratory_study_to_evaluate_tolerability_safety_and_activity_of_Ashwagandha_Withania_somnifera_in_healthy_volunteers 1250 mg, 8:1 =10000 mg. Divided so brought down UL slightly. ML - Based on 10:1 extract and traditional use equivalent to 5g dry root in a single serve. Typically used at 3-10g per day | DT7: Withania somnifera (Ashwagandha) root extract (10:1) equivalent Withania somnifera dry root equivalent withanolides (2.5%) | DU7: No warnings.
A8: W010004000 | B8: A | C8: 0.0022 | D8: Astragalus (Astragalus membranaceus) (root) extract | E8: Astragalus | F8: A355 | G8: Astragalus membranaceus | H8: Astragalus membranaceus | I8: Astragalus membranaceus | J8: root | K8: extract dry concentrate | L8: 20:1 | M8: 80% ethanol:water | N8: - | O8: - | P8: Astragalus membranaceus Root Ext Dry Conc (20:1 in 80% E:W) Equiv. dry root | Q8: Astragalus membranaceus (Astragalus) root extract equivalent Astragalus membranaceus dry root | R8: 10 | S8: mg | T8: 200 | U8: mg | Z8: - | AB8: 17.8102 | AC8: 1500 | AD8: 150 | AE8: Herb | AF8: Export Only, Listed, OTC, Prescription | AG8: 1302.19.90 | AH8: Highly refined organic chemicals and substances | AI8: Not required | AJ8: Not included in any CITES Appendix | AK8: No | AP8: dairy | BA8: soy | BB8: sulfites | BH8: sodium | BI8: 0.11 | BJ8: mg | BM8: sugars | BN8: 0.035 | BO8: mg | BR8: sugar alcohols | BS8: 14.6 | BT8: mg | BV8: 68522 | BW8: No restrictions. | BX8: No warnings. | BY8: No warnings. | CC8: carmellose sodium | CE8: colloidal anhydrous silica | CL8: vanilla flavour | CP8: glucose monohydrate | CQ8: glycerol | CT8: hypromellose | CU8: isomalt | CW8: lecithin | CX8: magnesium stearate | DB8: microcrystalline cellulose | DQ8: Yes | DR8: Yes | DS8: Therapeutic range 6-15 gm daily MT: 2-30 gm daily Braun and Cohen TR 150 mg - 900 mg of a 20:1 extract TR between MT & BC UL at BC top range | DT8: Astragalus membranaceus (Astragalus) root extract (20:1) equivalent Astragalus membranaceus dry root | DU8: No warnings.
A9: W010006000 | B9: A | C9: 0.0051 | D9: Eleuthero (Eleutherococcus senticosus) extract (root) (standardized to 0.8% eleutherosides) | E9: Siberian ginseng | F9: A2707 | G9: Eleutherococcus senticosus | H9: Eleutherococcus senticosus | I9: Eleutherococcus senticosus | J9: root | K9: extract dry concentrate standardised | L9: 15:1 | M9: 70% ethanol:water | N9: 0.8% eleutherosides | O9: - | P9: Eleutherococcus senticosus (Siberian ginseng) root ext dry conc std 15:1, 70% E/W Equiv. Eleutherococcus senticosus root dry Equiv. Eleutherosides (0.8%) | Q9: Eleutherococcus senticosus (Siberian ginseng) root extract equivalent Eleutherococcus senticosus dry root equivalent eleutherosides | R9: 10 | S9: mg | T9: 150 | U9: mg | V9: 0.8 | W9: mg | Z9: Please confirm the name and quantity of any excipients present? | AA9: 3% maltodextrin | AB9: 19.6902 | AC9: 500 | AD9: 500 | AE9: Herb | AF9: Export Only, Listed, OTC, Prescription | AG9: 1302.19.90 | AH9: Highly refined organic chemicals and substances | AI9: Not required | AJ9: Not included in any CITES Appendix | AK9: No | AP9: dairy | BA9: soy | BB9: sulfites | BH9: sodium | BI9: 0.1 | BJ9: mg | BM9: sugars | BN9: 0.033 | BO9: mg | BR9: sugar alcohols | BS9: 1.2 | BT9: mg | BV9: 60079 | BW9: No restrictions. | BX9: No warnings. | BY9: No warnings. | CC9: carmellose sodium | CE9: colloidal anhydrous silica | CL9: vanilla flavour | CP9: glucose monohydrate | CQ9: glycerol | CT9: hypromellose | CU9: isomalt | CW9: lecithin | CX9: magnesium stearate | CZ9: maltodextrin | DB9: microcrystalline cellulose | DQ9: Yes | DR9: Yes | DS9: Therapeutic range 3-4 gm daily MT TR 1-4 gm day BC TR 70 mg to 270 mg of a 15:1 extract 9BC reference range, UL reflects traditional dosing) | DT9: Eleutherococcus senticosus (Siberian ginseng) root extract (15:1) equivalent Eleutherococcus senticosus dry root equivalent eleutherosides (0.8%) | DU9: No warnings.
A10: W010007000 | B10: A | C10: 0.0038 | D10: Epigallocatechin gallate (EGCG) (Camellia sinensis) (standardized to 95% polyphenols) | E10: Green Tea (EGCG) | F10: A2486 | G10: Camellia sinensis | H10: Camellia sinensis | I10: Camellia sinensis | J10: leaf | K10: extract dry concentrate standardised | L10: 15:1 | M10: 50% ethanol:water | N10: 98% polyphenols 50% EGCG 1% caffeine | O10: - | P10: Camellia sinensis (Green tea) leaf ext dry conc std (15:1, 50% E/W) Equiv. Camellia sinensis leaf dry Equiv. EGCG (50%) Equiv. Caffeine (1%) | Q10: Camellia sinensis (Green tea) leaf extract equivalent Camellia sinensis dry leaf equivalent EGCG equivalent caffeine | R10: 10 | S10: mg | T10: 150 | U10: mg | V10: 5 | W10: mg | X10: 0.1 | Y10: mg | Z10: Please confirm the caffeine content, and the name and quantity of any excipients present? | AA10: NMT1% caffeine No excipients | AB10: 19.4502 | AC10: 1500 | AD10: 150 | AE10: Herb | AF10: Export Only, Listed, OTC, Prescription | AG10: 1302.19.90 | AH10: Highly refined organic chemicals and substances | AI10: Not required | AJ10: Not included in any CITES Appendix | AK10: No | AP10: dairy | BA10: soy | BB10: sulfites | BH10: sodium | BI10: 0.1 | BJ10: mg | BM10: sugars | BN10: 0.033 | BO10: mg | BV10: 94990 | BW10: Caffeine is a mandatory component of Camellia sinensis. When the medicine is packaged for supply as a divided preparation and is for internal use or oral application, the medicine must not contain a concentration of total caffeine greater than 33%. When for internal use or oral application, the maximum recommended daily dose of the medicine must provide no more than 400 mg of total caffeine. When the medicine is packaged for supply as an undivided preparation and is for internal use or oral application, the medicine must not contain a concentration of total caffeine greater than 1%. When the medicine is for internal use or oral application, a maximum recommended dose of the medicine must not provide more than 100 mg of total caffeine within a 3 hour period. | BX10: When the maximum recommended daily dose of the medicine provides greater than 10 mg of total caffeine and the medicine is for internal use or oral application, the following warning statements are required on the label: - (ADULT) 'Adults only' (or words to that effect). - (CAFF) 'Contains [state quantity per dosage unit or per mL or per gram of product] total caffeine [per dosage unit or per mL or per gram]. A cup of instant coffee contains approximately 80mg of caffeine.' - (CAFFPREG) ‘Caffeine intake more than 200 mg per day is not recommended during pregnancy or breastfeeding.’ When the maximum recommended daily dose of the medicine provides greater than 80 mg of total caffeine and the medicines is for internal use or oral application, the following warning statements are required on the label: - (CAFFLMT) 'Limit the use of caffeine-containing products (including tea and coffee) when taking this product.' - (CAFFCYP) ‘Caffeine interacts with enzyme CYP1A2 in the liver. Consult your health professional before taking with other medicines’ (or words to that effect). When used in oral medicines, the following warning statements are required on the medicine label: - 'In rare cases, Camellia sinensis may harm the liver. Stop use and see a doctor if you have yellowing skin/eyes, or unusual: fatigue, nausea, appetite loss, abdominal pain, dark urine, or itching.'; and - (FOOD) ‘To be taken with food.’ unless when: (a) the preparation of Camellia sinensis is derived from an aqueous extract and contains 300 mg or less epigallocatechin-3-gallate per maximum recommended daily dose; or (b) Camellia sinensis is used in combination with other permitted ingredients as a flavour proprietary excipient formulation. The total concentration of flavour proprietary excipient formulations containing Camellia sinensis must not be more than 5% of the total medicine. | BY10: When the maximum recommended daily dose provides greater than 10 mg of total caffeine, the following warning statements are required: "Contains caffeine. Not recommended for children or pregnant/lactating women. Contains [amount of caffeine in milligrams] mg of caffeine." | CC10: carmellose sodium | CE10: colloidal anhydrous silica | CL10: vanilla flavour | CN10: glacial acetic acid | CP10: glucose monohydrate | CW10: lecithin | CX10: magnesium stearate | DB10: microcrystalline cellulose | DF10: poliglusam | DQ10: Yes | DR10: Yes | DS10: Therapeutic range 1.5 - 3 gm daily MT toxicity of EGCG at >800 mg daily. TR should read 100-200 mg of a 15:1 extract UL 1500 mg of extract | DT10: Camellia sinensis (Green tea) leaf extract (15:1) equivalent Camellia sinensis dry leaf equivalent EGCG (50%) equivalent caffeine (1%) | DU10: "Contains [state quantity per dosage unit or per mL or per gram] total caffeine [per dosage unit or per mL or per gram]. A cup of instant coffee contains approximately 80mg of caffeine." "Caffeine intake more than 200 mg per day is not recommended for use by pregnant and lactating women." "Limit the use of caffeine containing products (including tea and coffee) when taking this product.." "Caffeine interacts with enzyme CYP1A2 in the liver. Consult a health professional before taking with other medicines." "In rare cases, Camellia sinensis may harm the liver." "Stop use and consult a healthcare professional if you have yellowing skin/eyes or unusual fatigue, nausea, appetite loss, abdominal pain, dark urine, or itching." "To be taken with food."
A11: W010008000 | B11: A | C11: 0.0051 | D11: Garlic (Allium sativum) extract (bulb) (20:1) | E11: Garlic | F11: A153 | G11: Allium sativum | H11: Allium sativum | I11: Allium sativum | J11: bulb | K11: extract dry concentrate | L11: 20:1 | M11: 75% ethanol:water | N11: - | O11: - | P11: Allium sativum (Garlic) bulb ext dry conc (20:1, 75% E/W) Equiv. Allium sativum bulb dry | Q11: Allium sativum (Garlic) bulb extract equivalent Allium sativum dry bulb | R11: 10 | S11: mg | T11: 200 | U11: mg | Z11: Please confirm the name and quantity of any excipients present? | AA11: No excipients | AB11: 19.8102 | AC11: 200 | AD11: 50 | AE11: Herb | AF11: Export Only, Listed, OTC, Prescription | AG11: 1302.19.90 | AH11: Highly refined organic chemicals and substances | AI11: Not required | AJ11: Not included in any CITES Appendix | AK11: No | AP11: dairy | BA11: soy | BB11: sulfites | BH11: sodium | BI11: 0.11 | BJ11: mg | BM11: sugars | BN11: 0.035 | BO11: mg | BV11: 59168 | BW11: No restrictions. | BX11: No warnings. | BY11: No warnings. | CC11: carmellose sodium | CE11: colloidal anhydrous silica | CJ11: ethanol | CL11: vanilla flavour | CP11: glucose monohydrate | CQ11: glycerol | CT11: hypromellose | CW11: lecithin | CX11: magnesium stearate | DB11: microcrystalline cellulose | DQ11: Yes | DR11: Yes | DS11: Therapeutic range TR 300 - 1500 mg/day BC TR 10mg - 80mg of 20:1 extract UL https://pubmed.ncbi.nlm.nih.gov/17325296/ | DT11: Allium sativum (Garlic) bulb extract (20:1) equivalent Allium sativum dry bulb | DU11: No warnings.
A12: W010009000 | B12: A | C12: 0.0035 | D12: Grape (Vitis vinifera) extract (seed) (standardized to 92-95% proanthocyanidins) | E12: Grape Seed | F12: A461 | G12: Vitis vinifera | H12: Vitis vinifera | I12: Vitis vinifera | J12: seed | K12: extract dry concentrate standardised | L12: 120:1 | M12: 70% ethanol:water | N12: 92-95% proanthocyanidins | O12: - | P12: Vitis vinifera seed dry ext conc std. (120:1 in 70:30 E:W) Equiv. Vitis vinifera seed dry Equiv. proanthocyanodins (92%) | Q12: Vitis vinifera (Grape) seed extract equivalent Vitis vinifera dry seed equivalent proanthocyanidins | R12: 10 | S12: mg | T12: 1200 | U12: mg | V12: 9.2 | W12: mg | Z12: - | AB12: 18.9802 | AC12: 600 | AD12: 200 | AE12: Herb | AF12: Export Only, Listed, OTC, Prescription | AG12: 1302.19.90 | AH12: Highly refined organic chemicals and substances | AI12: Not required | AJ12: Not included in any CITES Appendix | AK12: No | AP12: dairy | BA12: soy | BB12: sulfites | BH12: sodium | BI12: 0.2 | BJ12: mg | BM12: sugars | BN12: 0.033 | BO12: mg | BR12: sugar alcohols | BS12: 3.7 | BT12: mg | BV12: 83764 | BW12: No restrictions. | BX12: No warnings. | BY12: No warnings. | CC12: carmellose sodium | CE12: colloidal anhydrous silica | CL12: vanilla flavour | CP12: glucose monohydrate | CQ12: glycerol | CS12: hyprolose | CT12: hypromellose | CU12: isomalt | CW12: lecithin | CX12: magnesium stearate | DB12: microcrystalline cellulose | DQ12: Yes | DR12: Yes | DS12: TR 150- 400 mg daily BC (extract, need to check the ratio) cites endotelon need to confirm the ratio TR 150 - 400 mg of a 120:1 Matt confirmed | DT12: Vitis vinifera (Grape) seed extract equivalent Vitis vinifera dry seed equivalent proanthocyanidins (92%) | DU12: No warnings.
A13: W010011000 | B13: A | C13: 0.0083 | D13: Lutein | E13: Lutein | F13: A378 | G13: Lutein | H13: Tagetes erecta | I13: Tagetes erecta | J13: flower | K13: extract dry concentrate standardised | L13: 7:1 | M13: 100% hexane | N13: 7.5% lutein | O13: - | P13: Tagetes Erecta L. Flower Ext. Dry Conc. Std. (7:1 in 100% Hexane) Equiv. Tagetes erecta flower dry Equiv. Lutein (7.5%) Excipient: Maltodextrin 5% | Q13: Tagetes erecta (Aztec marigold) flower extract equivalent Tagetes erecta dry flower equivalent lutein | R13: 6.67 | S13: mg | T13: 46.7 | U13: mg | V13: 0.5 | W13: mg | Z13: - | AB13: 18.4612 | AC13: 540 | AD13: 20 | AE13: Herb | AF13: Export Only, Listed, OTC, Prescription | AG13: 2106.90.99 or 1302.19.90 | AH13: Highly refined organic chemicals and substances | AI13: Not required | AJ13: Not included in any CITES Appendix | AK13: No | AP13: dairy | BA13: soy | BB13: sulfites | BH13: sodium | BI13: 0.1 | BJ13: mg | BM13: sugars | BN13: 0.031 | BO13: mg | BV13: 84203 | BW13: No restrictions. | BX13: No warnings. | BY13: No warnings. | CC13: carmellose sodium | CE13: colloidal anhydrous silica | CL13: vanilla flavour | CP13: glucose monohydrate | CQ13: glycerol | CT13: hypromellose | CW13: lecithin | CX13: magnesium stearate | CZ13: maltodextrin | DB13: microcrystalline cellulose | DQ13: Yes | DR13: Yes | DS13: TR 80-270 mg mg/day of a 7:1 extract (gives 6-20 mg of lutein) reference BC | DT13: Tagetes erecta (Aztec marigold) flower extract equivalent Tagetes erecta dry flower equivalent lutein (7.5%) | DU13: No warnings.
A14: W010012000 | B14: A | C14: 0.0093 | D14: Zeaxanthin | E14: Zeaxanthin | F14: A379 | G14: Zeaxanthin | H14: - | I14: Zeaxanthin | J14: - | K14: - | L14: - | M14: - | N14: - | O14: 20% zeaxanthin | P14: Zeaxanthin Equiv. Zeaxanthin 20% Excipients: Maltodextrin 30% | Q14: Zeaxanthin | R14: 1 | S14: mg | Z14: - | AB14: 19.4902 | AC14: 10 | AD14: 2 | AE14: Vitamin | AF14: Export Only, Listed, OTC, Prescription | AG14: 2106.90.99 | AH14: Highly refined organic chemicals and substances | AI14: Not required | AJ14: Not included in any CITES Appendix | AK14: No | AP14: dairy | BA14: soy | BB14: sulfites | BH14: sodium | BI14: 0.1 | BJ14: mg | BM14: sugars | BN14: 0.033 | BO14: mg | BV14: 100386 | BW14: No restrictions. | BX14: No warnings. | BY14: No warnings. | CC14: carmellose sodium | CE14: colloidal anhydrous silica | CL14: vanilla flavour | CP14: glucose monohydrate | CQ14: glycerol | CT14: hypromellose | CW14: lecithin | CX14: magnesium stearate | CZ14: maltodextrin | DB14: microcrystalline cellulose | DQ14: Yes | DR14: Yes | DS14: TR 2-5 mg/day (BC, says 2-5 well tolerated) | DT14: Zeaxanthin | DU14: No warnings.
A15: W010013000 | B15: A | C15: 0.0048 | D15: Milk thistle (Silybum marianum) extract (standardized to 80% silymarin) | E15: Milk thistle | F15: A752 | G15: Silybum marianum | H15: Silybum marianum | I15: Silybum marianum | J15: fruit | K15: extract dry concentrate standardised | L15: 70:1 | M15: 95% ethyl acetate:water | N15: 80% silybin | O15: - | P15: Silybum marianum fruit dry ext conc std 70:1 (95:5 Ethyl acetate:water) Equiv. Silybum marianum fruit dry Equiv. silymarin 80% | Q15: Silybum marianum (Milk thistle) fruit extract equivalent Silybum marianum dry fruit equivalent silymarin | R15: 10 | S15: mg | T15: 700 | U15: mg | V15: 8 | W15: mg | Z15: - | AB15: 19.81 | AC15: 450 | AD15: 150 | AE15: Herb | AF15: Export Only, Listed, OTC, Prescription | AG15: 1302.19.90 | AH15: Highly refined organic chemicals and substances | AI15: Not required | AJ15: Not included in any CITES Appendix | AK15: No | AP15: dairy | BA15: soy | BB15: sulfites | BH15: sodium | BI15: 0.11 | BJ15: mg | BM15: sugars | BN15: 0.035 | BO15: mg | BR15: sugar alcohols | BS15: 4 | BT15: mg | BV15: 62088 | BW15: No restrictions. | BX15: No warnings. | BY15: No warnings. | CC15: carmellose sodium | CJ15: ethanol | CL15: vanilla flavour | CP15: glucose monohydrate | CQ15: glycerol | CT15: hypromellose | CU15: isomalt | CW15: lecithin | CX15: magnesium stearate | DB15: microcrystalline cellulose | DG15: pregelatinised starch | DQ15: Yes | DR15: Yes | DS15: Therapeutic range 6-12 gm daily MT - 200 mg of extract 100 - 170 mg of a 70:1 extract YSCP confirmed 450mg daily is fine. Clinical trials go up to 1500mg in clinical studies. https://link.springer.com/article/10.1186/s12906-025-04886-y | DT15: Silybum marianum (Milk thistle) fruit extract (70:1) equivalent Silybum marianum dry fruit equivalent silymarin (80%) | DU15: No warnings.
A16: W010017000 | B16: A | C16: 0.0029 | D16: Pine (Pinus massoniana) extract (bark) (standardized to 60-70% procyanidins) | E16: Pine Bark (Pycnogenol) | F16: A2768 | G16: Pinus massoniana | H16: Pinus massoniana | I16: Pinus massoniana | J16: bark | K16: extract dry concentrate standardised | L16: 50:1 | M16: 70% ethanol:water | N16: 60-70% procyanidins | O16: - | P16: Pinus massoniana bark extract dry conc std 50:1 (70:30 E:W) Equiv. Pinus massoniana bark dry Equiv. procyanodins 60-70% Excipient: Maltodextrin 15% | Q16: Pinus massoniana (Pine) bark extract equivalent Pinus massoniana dry bark equivalent procyanidins | R16: 7.15 | S16: mg | T16: 357.5 | U16: mg | V16: 4.3 | W16: mg | Z16: - | AB16: 17.4402 | AC16: 360 | AD16: 100 | AE16: Herb | AF16: Export Only, Listed, OTC, Prescription | AG16: 1302.19.90 | AH16: Highly refined organic chemicals and substances | AI16: Not required | AJ16: Not included in any CITES Appendix | AK16: No | AP16: dairy | BA16: soy | BB16: sulfites | BH16: sodium | BI16: 0.09 | BJ16: mg | BM16: sugars | BN16: 0.03 | BO16: mg | BV16: 85330 | BW16: When the plant preparation is oil or distillate the total concentration of Pinus massoniana oil or distillate in the preparation must be no more than 25%. | BX16: No warnings. | BY16: No warnings. | CC16: carmellose sodium | CE16: colloidal anhydrous silica | CL16: vanilla flavour | CP16: glucose monohydrate | CQ16: glycerol | CT16: hypromellose | CW16: lecithin | CX16: magnesium stearate | CZ16: maltodextrin | DB16: microcrystalline cellulose | DG16: pregelatinised starch | DQ16: Yes | DR16: Yes | DS16: TR 50-300 mg https://pubmed.ncbi.nlm.nih.gov/11081989/, TR 100-300 mg of a 50:1 extract ' equiv to 60 -240 mg of procyanidins UL 360 mg/day = extrapolated within safety margins, not standard RCT dose | DT16: Pinus massoniana (Pine) bark extract (50:1) equivalent Pinus massoniana dry bark equivalent procyanidins (60%) | DU16: No warnings.
A17: W010018000 | B17: A | C17: 0.0045 | D17: Pomegranate (Punica granatum) extract (hull) (standardized to 40% ellagic acid) | E17: Pomegranate | F17: A2365 | G17: Punica granatum | H17: Punica granatum | I17: Punica granatum | J17: hull | K17: extract dry concentrate standardised | L17: 18:1 | M17: 50% ethanol:water | N17: 40% ellagic acid | O17: - | P17: Punica granatum hull dry ext conc Std, 18:1, (50% EtOH: water) Equiv. Punica granatum hull dry Equiv. ellagic acid (40%) | Q17: Punica granatum (Pomegranate) hull extract equivalent Punica granatum dry hull equivalent ellagic acid | R17: 10 | S17: mg | T17: 180 | U17: mg | V17: 4 | W17: mg | Z17: - | AB17: 18.8102 | AC17: 1000 | AD17: 250 | AE17: Herb | AF17: Export Only, Listed, OTC, Prescription | AG17: 1302.19.90 | AH17: Highly refined organic chemicals and substances | AI17: Not required | AJ17: Not included in any CITES Appendix | AK17: No | AP17: dairy | BA17: soy | BB17: sulfites | BH17: sodium | BI17: 0.11 | BJ17: mg | BM17: sugars | BN17: 0.035 | BO17: mg | BV17: 93464 | BW17: No restrictions. | BX17: No warnings. | BY17: No warnings. | CC17: carmellose sodium | CE17: colloidal anhydrous silica | CJ17: ethanol | CL17: vanilla flavour | CP17: glucose monohydrate | CQ17: glycerol | CT17: hypromellose | CW17: lecithin | CX17: magnesium stearate | DB17: microcrystalline cellulose | DQ17: Yes | DR17: Yes | DS17: TR 50-750 gm of an 18:1 extract daily UL Fuster‑Márquez M, et al. Effects of pomegranate extract supplementation on metabolic and inflammatory markers. Nutrients. 2021. | DT17: Punica granatum (Pomegranate) hull extract (18:1) equivalent Punica granatum dry hull equivalent ellagic acid (40%) | DU17: No warnings.
A18: W010019000 | B18: A | C18: 0.0144 | D18: Trans-resveratrol | E18: Resveratrol | F18: A2143 | G18: Resveratrol | H18: - | I18: Resveratrol | J18: - | K18: - | L18: - | M18: - | N18: - | O18: 98% resveratrol | P18: Resveratrol (98%) | Q18: Resveratrol | R18: 10 | S18: mg | Z18: - | AB18: 18.4602 | AC18: 1500 | AD18: 150 | AE18: Synthetic | AF18: Export Only, Listed | AG18: 1302.19.90 | AH18: Highly refined organic chemicals and substances | AI18: Not required | AJ18: Not included in any CITES Appendix | AK18: No | AP18: dairy | BA18: soy | BB18: sulfites | BH18: sodium | BI18: 0.1 | BJ18: mg | BM18: sugars | BN18: 0.031 | BO18: mg | BR18: sugar alcohols | BS18: 2.58 | BT18: mg | BV18: 111032 | BW18: The maximum recommended daily dose of the medicine must not contain more than 150 milligrams of resveratrol. | BX18: The following warning statements are required on the medicine label: - (RESVER) 'Resveratrol may affect the way some medicines work, including Warfarin. Consult your health professional before taking with other medicines (or words to that effect).';- (PREGNT) ‘Not recommended for use by pregnant and lactating women’ (or words to that effect)’; and- (CHILD2) ‘Not suitable for children’. | BY18: No warnings. | CC18: carmellose sodium | CE18: colloidal anhydrous silica | CL18: vanilla flavour | CP18: glucose monohydrate | CQ18: glycerol | CT18: hypromellose | CU18: isomalt | CW18: lecithin | CX18: magnesium stearate | DB18: microcrystalline cellulose | DQ18: Yes | DR18: Yes | DS18: TR 150-500 mg daily common dosage, higher doses at 2 gm daily TR 150 -1000 mg daily, UL 5gm https://www.mdpi.com/1422-0067/25/2/747?utm YSCP confirmed 600mg Therapeutic Clinical use (most effective) (Chen S et al. 2015). 1000mg Aggressive Metabolic use. (Brown VA et al. 2010 (Cancer Research)1000mg to 1500mg Upper tolerable long-term. | DT18: Resveratrol | DU18: "Resveratrol may affect the way some medicines work, including warfarin. Consult a health professional before taking with other medicines." "Not recommended for use by pregnant and lactating women."
A19: W010020000 | B19: A | C19: 0.0122 | D19: Rhodiola (Rhodiola rosea) extract (root) (standardized to 3% rosavins and 1% salidroside) | E19: Rhodiola rosea (Rose Root) | F19: A790 | G19: Rhodiola rosea | H19: Rhodiola rosea | I19: Rhodiola rosea | J19: root | K19: extract dry concentrate standardised | L19: 10:1 | M19: 70% ethanol:water | N19: 3% rosavins, 1% salidroside | O19: - | P19: Rhodiola rosea (Rose root) root ext dry conc std (10:1, 70% E/W) Equiv. Rhodiola rosea root dry Equiv. Rosavins (3%) Equiv. Salidroside (1%) | Q19: Rhodiola rosea (Rose root) root extract equivalent Rhodiola rosea dry root equivalent rosavins equivalent salidroside | R19: 10 | S19: mg | T19: 100 | U19: mg | V19: 0.3 | W19: mg | X19: 0.1 | Y19: mg | Z19: Please confirm the name and quantity of any excipients present? | AA19: No excipients | AB19: 18.6702 | AC19: 600 | AD19: 200 | AE19: Herb | AF19: Export Only, Listed, OTC, Prescription | AG19: 1302.19.90 | AH19: Highly refined organic chemicals and substances | AI19: Not required | AJ19: CITES Appendix II | AK19: Department of Climate Change, Energy, the Environment and Water - Wildlife trade permit required for Raw Material only, not formulated products | AP19: dairy | BA19: soy | BB19: sulfites | BH19: sodium | BI19: 0.11 | BJ19: mg | BM19: sugars | BN19: 0.035 | BO19: mg | BR19: sugar alcohols | BS19: 1.2 | BT19: mg | BV19: 104774 | BW19: Only for use in oral medicines. Only available for use when the plant preparation is dry root powder, dry root powder as an aqueous extract or dry root powder as a hydroethanolic extract with no more than 70% ethanol v/v. | BX19: No warnings. | BY19: No warnings. | CC19: carmellose sodium | CE19: colloidal anhydrous silica | CL19: vanilla flavour | CN19: glacial acetic acid | CP19: glucose monohydrate | CU19: isomalt | CW19: lecithin | CX19: magnesium stearate | DB19: microcrystalline cellulose | DF19: poliglusam | DQ19: Yes | DR19: Yes | DS19: Therapeutic range 1-2 gm daily (MT) Research at 600 mg of Rhodiola extract in depression (HWT (6,000 mg) TR 200-400 mg daily of a 10:1 extract UL 680 MG Clinical trial of Rhodiola rosea L. extract SHR-5 in the treatment of mild to moderate depression V Darbinyan 1, G Aslanyan, E Amroyan, E Gabrielyan, C Malmström, A Panossian | DT19: Rhodiola rosea (Rose root) root extract (10:1) equivalent Rhodiola rosea dry root equivalent rosavins (3%) equivalent salidroside (1%) | DU19: No warnings.
A20: W010022000 | B20: A | C20: 0.0016 | D20: Boswellia serrata extract (standardized to 60% boswellic acids) | E20: Boswellia (Frankincense) | F20: A319 | G20: Boswellia serrata | H20: Boswellia serrata | I20: Boswellia serrata | J20: sap resin | K20: extract dry concentrate standardised | L20: 6:1 | M20: 98% ethanol:water | N20: 60% boswellic acids | O20: - | P20: Boswellia Serrata sap resin Ext. Dry Conc std (6:1 98% E/W) Equiv. Boswellia Serrata sap resin dry. Equiv. Boswellic acids (60%) | Q20: Boswellia serrata (Frankincense) sap resin extract equivalent Boswellia serrata dry sap resin equivalent boswellic acids | R20: 5 | S20: mg | T20: 30 | U20: mg | V20: 3 | W20: mg | Z20: - | AB20: 18.3102 | AC20: 1200 | AD20: 800 | AE20: Herb | AF20: Export Only, Listed, OTC, Prescription | AG20: 1302.19.90 | AH20: Highly refined organic chemicals and substances | AI20: Not required | AJ20: Not included in any CITES Appendix | AK20: No | AP20: dairy | BA20: soy | BB20: sulfites | BH20: sodium | BI20: 0.11 | BJ20: mg | BM20: sugars | BN20: 0.035 | BO20: mg | BV20: 96819 | BW20: No restrictions. | BX20: No warnings. | BY20: No warnings. | CC20: carmellose sodium | CE20: colloidal anhydrous silica | CL20: vanilla flavour | CP20: glucose monohydrate | CQ20: glycerol | CT20: hypromellose | CW20: lecithin | CX20: magnesium stearate | CZ20: maltodextrin | DB20: microcrystalline cellulose | DQ20: Yes | DR20: Yes | DS20: TR: 300-400 mg standardised extract, 3 times daily MT TR 800 - 1000 mg of a 6:1 extract UL https://pubmed.ncbi.nlm.nih.gov/17764013/ | DT20: Boswellia serrata (Frankincense) sap resin extract (6:1) equivalent Boswellia serrata dry sap resin equivalent boswellic acids (60%) | DU20: No warnings.
A21: W010023000 | B21: A | C21: 0.0026 | D21: Betaine (Trimethylglycine) | E21: Betaine (Trimethylglycine) | F21: A2232 | G21: Betaine | H21: - | I21: Betaine | J21: - | K21: - | L21: - | M21: - | N21: - | O21: - | P21: Betaine | Q21: Betaine | R21: 5 | S21: mg | Z21: - | AB21: 18.8102 | AC21: 6000 | AD21: 1000 | AE21: Amino acid | AF21: Export Only, OTC, Prescription | AG21: 2923.90.00 | AH21: Highly refined organic chemicals and substances | AI21: Not required | AJ21: Not included in any CITES Appendix | AK21: No | AP21: dairy | BA21: soy | BB21: sulfites | BH21: sodium | BI21: 0.11 | BJ21: mg | BM21: sugars | BN21: 0.035 | BO21: mg | BR21: sugar alcohols | BS21: 9.5 | BT21: mg | BV21: 67679 | BW21: Only for use in topical medicines for dermal application. | BX21: No warnings. | BY21: No warnings. | CC21: carmellose sodium | CE21: colloidal anhydrous silica | CL21: vanilla flavour | CP21: glucose monohydrate | CQ21: glycerol | CT21: hypromellose | CU21: isomalt | CW21: lecithin | CX21: magnesium stearate | DB21: microcrystalline cellulose | DQ21: Yes | DR21: Yes | DS21: TR 2.5 - 6 gm daily https://pubmed.ncbi.nlm.nih.gov/12730412/ TR 1000 mg to 4000 mg daily UL 6 gm YSCP confirmed 600mg Therapeutic Clinical use (most effective) (Chen S et al. 2015). 1000mg Aggressive Metabolic use. (Brown VA et al. 2010 (Cancer Research)1000mg to 1500mg Upper tolerable long-term. | DT21: Betaine (Trimethylglycine) | DU21: No warnings.
A22: W010024000 | B22: A | C22: 0.0054 | D22: Liquorice extract (root) | E22: Licorice DGL | F22: A2657 | G22: Glycyrrhiza glabra | H22: Glycyrrhiza glabra | I22: Glycyrrhiza glabra | J22: root | K22: extract dry concentrate standardised | L22: 8:1 | M22: 100% water | N22: 1.5% glycyrrhizin | O22: - | P22: Glycyrrhiza glabra Root Ext. Dry Conc. Std. (8:1 in 100% Water) Equiv. Glycyrrhiza glabra root dry Equiv. Glycyrrhizin 1.5% Excipient: Maltodextrin 5% | Q22: Glycyrrhiza glabra (Liquorice) root extract equivalent Glycyrrhiza glabra dry root equivalent glycyrrhizin | R22: 10 | S22: mg | T22: 80 | U22: mg | V22: 0.15 | W22: mg | Z22: - | AB22: 19.4902 | AC22: 1000 | AD22: 150 | AE22: Herb | AF22: Export Only, Listed, OTC, Prescription | AG22: 1302.12.00 | AH22: Highly refined organic chemicals and substances | AI22: Not required | AJ22: Not included in any CITES Appendix | AK22: No | AP22: dairy | BA22: soy | BB22: sulfites | BH22: sodium | BI22: 0.1 | BJ22: mg | BM22: sugars | BN22: 0.033 | BO22: mg | BR22: sugar alcohols | BS22: 1.5 | BT22: mg | BV22: 62323 | BW22: No restrictions. | BX22: No warnings. | BY22: No warnings. | CC22: carmellose sodium | CE22: colloidal anhydrous silica | CL22: vanilla flavour | CP22: glucose monohydrate | CQ22: glycerol | CT22: hypromellose | CU22: isomalt | CW22: lecithin | CX22: magnesium stearate | CZ22: maltodextrin | DB22: microcrystalline cellulose | DQ22: Yes | DR22: Yes | DS22: TR 1.5-6 gm daily ABC (Murray and Pizorno) 3.8 gm for ulcers BC in 5 divided doses I think we can stay at 300 mg because it is 1 daily dose. TR is 150mg - 300 mg of a 6:1 extract daily, UL is higher because of safety of DGL | DT22: Glycyrrhiza glabra (Licorice) root extract (8:1) equivalent Glycyrrhiza glabra dry root equivalent glycyrrhizin (1.5%) | DU22: No warnings.
A23: W010025000 | B23: A | C23: 0.008 | D23: Dong quai (Angelica polymorpha) extract (root) (standardized to 0.25% ligustilide) | E23: Dong quai | F23: A2720 | G23: Angelica polymorpha | H23: Angelica polymorpha | I23: Angelica polymorpha | J23: root | K23: extract dry concentrate standardised | L23: 2:1 | M23: 50% ethanol:water | N23: 0.25% ligustilide | O23: - | P23: Angelica polymorpha (Dong quai) root ext dry conc std (2:1, 50% E/W) Equiv. Angelica polymorpha root dry Equiv. Ligustilide (0.25%) | Q23: Angelica polymorpha (Dong quai) root extract equivalent Angelica polymorpha dry root equivalent ligustilide | R23: 10 | S23: mg | T23: 20 | U23: mg | V23: 0.02 | W23: mg | Z23: Please confirm the name and quantity of any excipients present? | AA23: No excipients | AB23: 19.8102 | AC23: 6000 | AD23: 500 | AE23: Herb | AF23: Export Only, Listed, OTC, Prescription | AG23: 1302.19.90 | AH23: Highly refined organic chemicals and substances | AI23: Not required | AJ23: Not included in any CITES Appendix | AK23: No | AP23: dairy | BA23: soy | BB23: sulfites | BH23: sodium | BI23: 0.11 | BJ23: mg | BM23: sugars | BN23: 0.035 | BO23: mg | BV23: 72121 | BW23: No restrictions. | BX23: No warnings. | BY23: No warnings. | CC23: carmellose sodium | CE23: colloidal anhydrous silica | CL23: vanilla flavour | CP23: glucose monohydrate | CQ23: glycerol | CT23: hypromellose | CW23: lecithin | CX23: magnesium stearate | DB23: microcrystalline cellulose | DQ23: Yes | DR23: Yes | DS23: TR 2-4 gram daily KB TR is 500 - 2000 mg of a 2:1 extract daily | DT23: Angelica polymorpha (Dong quai) root extract (2:1) equivalent Angelica polymorpha dry root equivalent ligustilide (0.25%) | DU23: No warnings.
A24: W010026000 | B24: A | C24: 0.0074 | D24: Berberine HCl | E24: Berberine HCL (Indian Barberry) | F24: A2412 | G24: Berberis aristata | H24: Berberis aristata | I24: Berberis aristata | J24: root | K24: extract dry concentrate standardised | L24: 40:1 | M24: 100% methanol | N24: 95% berberine hydrochloride | O24: - | P24: Berberis aristata root extract 40:1 (100% Methanol) Equiv. Berberis aristata root dry Equiv. Berberine Hydrochloride (95%) | Q24: Berberis aristata (Indian barberry) root extract equivalent Berberis aristata dry root equivalent berberine hydrochloride | R24: 10.53 | S24: mg | T24: 421.2 | U24: mg | V24: 10 | W24: mg | Z24: - | AB24: 19.4532 | AC24: 1500 | AD24: 500 | AE24: Herb | AF24: Export Only, Listed | AG24: 1302.19.90 | AH24: Highly refined organic chemicals and substances | AI24: Not required | AJ24: Not included in any CITES Appendix | AK24: No | AP24: dairy | BA24: soy | BB24: sulfites | BH24: sodium | BI24: 0.1 | BJ24: mg | BM24: sugars | BN24: 0.033 | BO24: mg | BV24: 110503 | BW24: Only for use in oral medicines. | BX24: The medicine requires the following warning statement on the medicine label:- (PREGNT) 'Not recommended for use by pregnant and lactating women' (or words to that effect). | BY24: No warnings. | CC24: carmellose sodium | CE24: colloidal anhydrous silica | CL24: vanilla flavour | CN24: glacial acetic acid | CP24: glucose monohydrate | CW24: lecithin | CX24: magnesium stearate | DB24: microcrystalline cellulose | DF24: poliglusam | DQ24: Yes | DR24: Yes | DS24: 500-1000 mg daily BC, TR is 500 - 1000 mg of a 40:1 extract, 1500 mg is UL equiv to 1425 mg of berberine (checked berberine content with Matt) | DT24: Berberis aristata (Indian barberry) root extract (40:1) equivalent Berberis aristata dry root equivalent berberine hydrochloride (95%) | DU24: "Not recommended for use by pregnant and lactating women."
A25: W010028000 | B25: A | C25: 0.0048 | D25: Maca (Lepidium meyenii) extract (standardised to 0.6% glucosinates) | E25: Maca (fruit) | F25: A2710 | G25: Lepidium meyenii | H25: Lepidium meyenii | I25: Lepidium meyenii | J25: fruit | K25: extract dry concentrate standardised | L25: 18:1 | M25: 20% ethanol:water | N25: 0.6% glucosinates | O25: - | P25: Lepidium meyenii fruit ext dry conc std (18-20:1 in 20:80 E:W) Equiv. Fruit dry Equiv. glucosinates (0.6%) | Q25: Lepidium meyenii (Maca) fruit extract equivalent Lepidium meyenii dry fruit equivalent glucosinates | R25: 10 | S25: mg | T25: 180 | U25: mg | V25: 0.06 | W25: mg | Z25: - | AB25: 19.4902 | AC25: 4000 | AD25: 700 | AE25: Herb | AF25: Export Only, Listed | AG25: 1302.19.90 | AH25: Highly refined organic chemicals and substances | AI25: Not required | AJ25: Not included in any CITES Appendix | AK25: No | AP25: dairy | BA25: soy | BB25: sulfites | BH25: sodium | BI25: 0.1 | BJ25: mg | BM25: sugars | BN25: 0.033 | BO25: mg | BR25: sugar alcohols | BS25: 1.2 | BT25: mg | BV25: 104787 | BW25: The route of administration for medicines that contain Lepidium meyenii must be limited to oral. The ingredient must consist of the dried tuber of Lepidium meyenii only. The maximum recommended daily dose of the medicine must not provide more than 3.5 g of Lepidium meyenii dried tuber (or its extract equivalent). | BX25: No warnings. | BY25: No warnings. | CC25: carmellose sodium | CE25: colloidal anhydrous silica | CJ25: ethanol | CL25: vanilla flavour | CP25: glucose monohydrate | CQ25: glycerol | CT25: hypromellose | CU25: isomalt | CW25: lecithin | CX25: magnesium stearate | DB25: microcrystalline cellulose | DQ25: Yes | DR25: Yes | DS25: TR 2- 3.5 gm daily. Toxicity studies show safety at 7.5 g/kg (rats) and 15g/kg on mice, suggesting it is safe in high doses (Meissner, 2006) BC TR is 700mg to 3,500 mg of a 18:1 extract daily | DT25: Lepidium meyenii (Maca) fruit extract (18:1) equivalent Lepidium meyenii dry fruit equivalent glucosinates (0.6%) | DU25: No warnings.
A26: W010029000 | B26: A | C26: 0.0038 | D26: Turmeric (Curcuma longa) extract (root) (standardized to contain 40% curcuminoids) | E26: Turmeric (Curcumin) | F26: A2740 | G26: Curcuma longa | H26: Curcuma longa | I26: Curcuma longa | J26: root | K26: extract dry concentrate standardised | L26: 25:1 | M26: 65% ethanol:water | N26: 40% curcuminoids | O26: - | P26: Curcuma longa (Turmeric) root ext dry conc std (25:1, 54% E/W) Equiv. Curcuma longa root dry Equiv. Curcuminoids (40%) | Q26: Curcuma longa (Turmeric) root extract equivalent Curcuma longa dry root equivalent curcuminoids | R26: 10 | S26: mg | T26: 250 | U26: mg | V26: 4 | W26: mg | Z26: Please confirm the name and quantity of any excipients present? | AA26: 60% maltodextrin | AB26: 19.8102 | AC26: 1000 | AD26: 300 | AE26: Herb | AF26: Export Only, Listed, OTC, Prescription | AG26: 1302.19.90 | AH26: Highly refined organic chemicals and substances | AI26: Not required | AJ26: Not included in any CITES Appendix | AK26: No | AP26: dairy | BA26: soy | BB26: sulfites | BH26: sodium | BI26: 0.1 | BJ26: mg | BM26: sugars | BN26: 0.033 | BO26: mg | BV26: 65400 | BW26: When used in oral medicines the maximum daily dose of (1E,6E)-1,7-bis(4-hydroxy-3-methoxyphenyl)-1,6-heptadiene-3,5-dione in the medicine must not provide more than: (a) 36 mg for children from 2-3 years (inclusive); (b) 48 mg for children from 4-11 years (inclusive); and (c) 123 mg for children from 12-17 years (inclusive). Not permitted for use in children aged below 2 years. | BX26: When used in oral medicines as an active ingredient, the following warning statement is required on the medicine label: ‘In very rare cases, Curcuma species may harm the liver. Stop use and see a doctor if you have yellowing skin/eyes or unusual: fatigue, nausea, appetite loss, abdominal pain, dark urine, or itching.’ | BY26: No warnings. | CC26: carmellose sodium | CE26: colloidal anhydrous silica | CL26: vanilla flavour | CP26: glucose monohydrate | CQ26: glycerol | CT26: hypromellose | CW26: lecithin | CX26: magnesium stearate | CZ26: maltodextrin | DB26: microcrystalline cellulose | DQ26: Yes | DR26: Yes | DS26: Therapuetic range 12 gm daily MT TR IS 300-1000 mg of a 25:1 extract daily No UL YSCP confirmed 1,000–1,500 mg/day Evidence-Based Clinical Dosing | DT26: Curcuma longa (Turmeric) root extract (25:1) equivalent Curcuma longa dry root equivalent curcuminoids (40%) | DU26: "In very rare cases, curcuma species may harm the liver." "Stop use and consult a healthcare professional if you have yellowing skin/eyes or unusual fatigue, nausea, appetite loss, abdominal pain, dark urine, or itching."
A27: W010030000 | B27: A | C27: 0.0086 | D27: Fenugreek (Trigonella foenum-graecum) extract (seed) (standardized to 50% saponins) | E27: Fenugreek | F27: A2737 | G27: Trigonella foenum-graecum | H27: Trigonella foenum-graecum | I27: Trigonella foenum-graecum | J27: seed | K27: extract dry concentrate standardised | L27: 50:1 | M27: 50% ethanol:water | N27: 50% saponins | O27: - | P27: Trigonella foenum-graecum (Fenugreek) seed dry ext conc std. 50:1, (50:50 E:W) Equiv. Trigonella foenum-graecum seed dry Equiv. saponins 50% | Q27: Trigonella foenum-graecum (Fenugreek) seed extract equivalent Trigonella foenum-graecum dry seed equivalent saponins | R27: 5 | S27: mg | T27: 250 | U27: mg | V27: 2.5 | W27: mg | Z27: - | AB27: 18.9502 | AC27: 200 | AD27: 50 | AE27: Herb | AF27: Export Only, Listed, OTC, Prescription | AG27: 1302.19.90 | AH27: Highly refined organic chemicals and substances | AI27: Not required | AJ27: Not included in any CITES Appendix | AK27: No | AP27: dairy | BA27: soy | BB27: sulfites | BH27: sodium | BI27: 0.1 | BJ27: mg | BM27: sugars | BN27: 0.033 | BO27: mg | BR27: sugar alcohols | BS27: 1.5 | BT27: mg | BV27: 59791 | BW27: No restrictions. | BX27: No warnings. | BY27: No warnings. | CC27: carmellose sodium | CE27: colloidal anhydrous silica | CL27: vanilla flavour | CN27: glacial acetic acid | CP27: glucose monohydrate | CU27: isomalt | CW27: lecithin | CX27: magnesium stearate | DB27: microcrystalline cellulose | DF27: poliglusam | DQ27: Yes | DR27: Yes | DS27: Therapeutic range 2-4 gm daily MT, aligns with BC TR 50mg to 100 mg of a 50:1 extract | DT27: Trigonella foenum-graecum (Fenugreek) seed extract (50:1) equivalent Trigonella foenum-graecum dry seed equivalent saponins (50%) | DU27: No warnings.
A28: W010031000 | B28: A | C28: 0.0045 | D28: Quercetin | E28: Quercetin | F28: A090 | G28: Quercetin | H28: - | I28: Quercetin dihydrate | J28: - | K28: - | L28: - | M28: - | N28: - | O28: 88% quercetin | P28: Quercetin dihydrate Equiv. Quercetin (88%) | Q28: Quercetin dihydrate equivalent quercetin | R28: 11.36 | S28: mg | T28: 10 | U28: mg | Z28: There are two forms, quercetin, and quercetin dihydrate. Please confirm which form is being used? | AA28: Quercetin dihydrate | AB28: 17.47 | AC28: 2000 | AD28: 250 | AE28: Herb | AF28: Export Only, Listed, OTC, Prescription | AG28: 1302.19.90 | AH28: Highly refined organic chemicals and substances | AI28: Not required | AJ28: Not included in any CITES Appendix | AK28: No | AP28: dairy | BA28: soy | BB28: sulfites | BH28: sodium | BI28: 0.11 | BJ28: mg | BM28: sugars | BN28: 0.035 | BO28: mg | BR28: sugar alcohols | BS28: 0.01 | BT28: mg | BV28: 106686 | BW28: No restrictions. | BX28: No warnings. | BY28: No warnings. | CC28: carmellose sodium | CE28: colloidal anhydrous silica | CL28: vanilla flavour | CN28: glacial acetic acid | CP28: glucose monohydrate | CT28: hypromellose | CU28: isomalt | CW28: lecithin | CX28: magnesium stearate | DB28: microcrystalline cellulose | DF28: poliglusam | DQ28: Yes | DR28: Yes | DS28: TR 150mg-2000 gm daily. Well tolerated and appears to be associated with little toxicity orally or IV (Lamson and Brignall 2000) BC UL 2gm | DT28: Quercetin dihydrate equivalent quercetin (88%) | DU28: No warnings.
A29: W010032000 | B29: A | C29: 0.0045 | D29: Cinnamon (Cinnamomum cassia) extract (bark) (standardized to 10% polyphenols) | E29: Cinnamon | F29: A2717 | G29: Cinnamomum cassia | H29: Cinnamomum cassia | I29: Cinnamomum cassia | J29: bark | K29: extract dry concentrate standardised | L29: 4:1 | M29: 70% ethanol:water | N29: 10% polyphenols | O29: - | P29: Cinnamomum cassia (Cinnamon) bark ext dry conc std (4:1, 70% E/W) Equiv. Cinnamomum cassia bark dry Equiv. Polyphenols (10%) | Q29: Cinnamomum cassia (Cinnamon) bark extract equivalent Cinnamomum cassia dry bark equivalent polyphenols | R29: 5 | S29: mg | T29: 20 | U29: mg | V29: 0.5 | W29: mg | Z29: Please confirm the name and quantity of any excipients present? | AA29: No excipients | AB29: 19.4702 | AC29: 1500 | AD29: 150 | AE29: Herb | AF29: Export Only, Listed, OTC, Prescription | AG29: 1302.19.90 | AH29: Highly refined organic chemicals and substances | AI29: Not required | AJ29: Not included in any CITES Appendix | AK29: No | AP29: dairy | BA29: soy | BB29: sulfites | BH29: sodium | BI29: 0.11 | BJ29: mg | BM29: sugars | BN29: 0.035 | BO29: mg | BV29: 67430 | BW29: Cassia oil is a mandatory component of Cinnamomum cassia if the plant preparation is an essential oil, distillate, fixed oil or infused oil. The concentration of Cassia oil in the medicine must be no more than 2%. When used as an active ingredient, the concentration of coumarin in the medicine must be no more than 0.001%. | BX29: No warnings. | BY29: No warnings. | CC29: carmellose sodium | CE29: colloidal anhydrous silica | CL29: vanilla flavour | CN29: glacial acetic acid | CP29: glucose monohydrate | CW29: lecithin | CX29: magnesium stearate | DB29: microcrystalline cellulose | DF29: poliglusam | DQ29: Yes | DR29: Yes | DS29: TR 1 - 6 gm daily (BC) 1.5-4 gm up to 4 times daily (BC) Generally well tolerated (BC) TR 250 mg - 1000 mg of a 4:1 extract daily No UL | DT29: Cinnamomum cassia (Cinnamon) bark extract (4:1) equivalent Cinnamomum cassia dry bark equivalent polyphenols (10%) | DU29: No warnings.
A30: W010033000 | B30: A | C30: 0.0067 | D30: Lemon balm (Melissa officinalis) extract (standardized to 3% rosmaric acid) | E30: Lemon balm | F30: A2914 | G30: Melissa officinalis | H30: Melissa officinalis | I30: Melissa officinalis | J30: herb | K30: extract dry concentrate standardised | L30: 4:1 | M30: 100% water | N30: 3% rosmarinic acid | O30: - | P30: Melissa officinalis (Lemon balm) herb ext dry conc std 4:1 (100% water), Equiv. rosmaric acid (3%) | Q30: Melissa officinalis (Lemon balm) herb extract equivalent Melissa officinalis dry herb equivalent rosmarinic acid | R30: 10 | S30: mg | T30: 40 | U30: mg | V30: 0.3 | W30: mg | Z30: - | AB30: 20.0002 | AC30: 3300 | AD30: 200 | AE30: Herb | AF30: Export Only, Listed, OTC, Prescription | AG30: 1302.19.90 | AH30: Highly refined organic chemicals and substances | AI30: Not required | AJ30: Not included in any CITES Appendix | AK30: No | AP30: dairy | BA30: soy | BB30: sulfites | BH30: sodium | BI30: 0.11 | BJ30: mg | BM30: sugars | BN30: 0.035 | BO30: mg | BR30: sugar alcohols | BS30: 3 | BT30: mg | BV30: 60154 | BW30: No restrictions. | BX30: No warnings. | BY30: No warnings. | CC30: carmellose sodium | CE30: colloidal anhydrous silica | CL30: vanilla flavour | CP30: glucose monohydrate | CQ30: glycerol | CT30: hypromellose | CU30: isomalt | CW30: lecithin | CX30: magnesium stearate | DB30: microcrystalline cellulose | DQ30: Yes | DR30: Yes | DS30: Therapeutic range 6-12 gm daily MT TR 4.5- 13.5 gm/day BC TR is 400 mg - 3000 mg of a 4:1 daily extract ROUNDED DOWN to even No. of granules | DT30: Melissa officinalis (Lemon balm) herb extract (4:1) equivalent Melissa officinalis dry herb equivalent rosmarinic acid (3%) | DU30: No warnings.
A31: W010034000 | B31: A | C31: 0.007 | D31: Passionflower (Passiflora incarnata) extract (standardized to 4% flavonoids) | E31: Passionflower | F31: A2915 | G31: Passiflora incarnata | H31: Passiflora incarnata | I31: Passiflora incarnata | J31: herb | K31: extract dry concentrate standardised | L31: 10:1 | M31: 70% ethanol:water | N31: 4% flavonoids | O31: - | P31: Passiflora incarnata (Passionflower) herb extract equivalent Passiflora incarnata dry herb equivalent flavonoids | Q31: Passiflora incarnata (Passionflower) herb extract equivalent Passiflora incarnata dry herb equivalent flavonoids | R31: 10 | S31: mg | T31: 100 | U31: mg | V31: 0.4 | W31: mg | Z31: Please confirm the name and quantity of any excipients present? | AA31: 10% maltodextrin | AB31: 18.4602 | AC31: 800 | AD31: 200 | AE31: Herb | AF31: Export Only, Listed, OTC, Prescription | AG31: 1302.19.90 | AH31: Highly refined organic chemicals and substances | AI31: Not required | AJ31: Not included in any CITES Appendix | AK31: No | AP31: dairy | BA31: soy | BB31: sulfites | BH31: sodium | BI31: 0.1 | BJ31: mg | BM31: sugars | BN31: 0.031 | BO31: mg | BV31: 59183 | BW31: No restrictions. | BX31: No warnings. | BY31: No warnings. | CC31: carmellose sodium | CE31: colloidal anhydrous silica | CL31: vanilla flavour | CP31: glucose monohydrate | CQ31: glycerol | CT31: hypromellose | CW31: lecithin | CX31: magnesium stearate | CZ31: maltodextrin | DB31: microcrystalline cellulose | DQ31: Yes | DR31: Yes | DS31: Therapeutic range 2-8 gm daily MT TR 200 - 700 mg daily of a 10:1 extract, UL 800 mg MT | DT31: Passiflora incarnata (Passionflower) herb extract (10:1) equivalent Passiflora incarnata dry herb equivalent flavonoids (4%) | DU31: No warnings.
A32: W010037000 | B32: A | C32: 0.009 | D32: California poppy extract (herb) (4:1) | E32: California poppy | F32: A660 | G32: Eschscholzia californica | H32: Eschscholzia californica | I32: Eschscholzia californica | J32: herb | K32: extract dry concentrate | L32: 4:1 | M32: 70% ethanol:water | N32: - | O32: - | P32: Eschscholzia californica (California poppy) herb ext dry conc (4:1, 70% E/W) Equiv. Eschscholzia californica herb dry | Q32: Eschscholzia californica (California poppy) herb extract equivalent Eschscholzia californica dry herb | R32: 5 | S32: mg | T32: 20 | U32: mg | Z32: Please confirm the name and quantity of any excipients present? | AA32: NMT 30% maltodextrin | AB32: 198.2802 | AC32: 1000 | AD32: 300 | AE32: Herb | AF32: Export Only, Listed, OTC, Prescription | AG32: 1302.19.90 | AH32: Highly refined organic chemicals and substances | AI32: Not required | AJ32: Not included in any CITES Appendix | AK32: No | AP32: dairy | BA32: soy | BB32: sulfites | BH32: sodium | BI32: 0.1 | BJ32: mg | BM32: sugars | BN32: 0.031 | BO32: mg | BV32: 108194 | BW32: No restrictions. | BX32: No warnings. | BY32: No warnings. | CC32: carmellose sodium | CE32: colloidal anhydrous silica | CL32: vanilla flavour | CP32: glucose monohydrate | CQ32: glycerol | CT32: hypromellose | CW32: lecithin | CX32: magnesium stearate | CZ32: maltodextrin | DB32: microcrystalline cellulose | DQ32: Yes | DR32: Yes | DS32: TR 300-1000 mg/day DEE BHP TR 300mg - 600 mg of a 4:1 extract daily, UL 1000 mg | DT32: Eschscholzia californica (California poppy) herb extract (4:1) equivalent Eschscholzia californica dry herb | DU32: No warnings.
